<mujoco>
  <compiler/>
  <!-- Car Asset from https://github.com/google-deepmind/mujoco/blob/main/model/car/car.xml -->
  <asset>
    <texture name="grid" type="2d" builtin="checker" width="512" height="512" rgb1=".1 .2 .3" rgb2=".2 .3 .4"/>
    <material name="grid" texture="grid" texrepeat="1 1" texuniform="true" reflectance=".2"/>
    <mesh name="chasis" scale=".01 .006 .0015"
      vertex=" 9   2   0
              -10  10  10
               9  -2   0
               10  3  -10
               10 -3  -10
              -8   10 -10
              -10 -10  10
              -8  -10 -10
              -5   0   20"/>
  </asset>

  <default>
    <joint damping=".03"/>
    <default class="wheel">
      <geom type="cylinder" size=".03 .01" rgba=".5 .5 1 1"/>
    </default>
    <default class="decor">
      <site type="box" rgba=".5 1 .5 1"/>
    </default>
  </default>

  <worldbody>
    <geom type="plane" size="3 3 .01" material="grid"/>
    <body pos="0.5 0.2 0" name="table0">
        <geom size="0.01 0.5 0.1" type="box" mass="2000" rgba="1 0 0 1"></geom>
    </body>
    <body pos="0.2 0.7 0" name="table1">
        <geom size="0.3 0.01 0.1" type="box" mass="2000" rgba="1 0 0 1"></geom>
    </body>
    <body pos="-0.2 0.2 0" name="table2">
        <geom size="0.3 0.01 0.1" type="box" mass="2000" rgba="1 0 0 1"></geom>
    </body>
    <body pos="-.5 0.25 0" name="table3">
        <geom size="0.01 .95 0.1" type="box" mass="2000" rgba="1 0 0 1"></geom>
    </body>
    <body pos="0.2 1.2 0" name="table4">
        <geom size=".7 0.01 0.1" type="box" mass="2000" rgba="1 0 0 1"></geom>
    </body>
    <body pos="0.2 -.7 0" name="table5">
        <geom size=".7 0.01 0.1" type="box" mass="2000" rgba="1 0 0 1"></geom>
    </body>
    <body pos="0.2 -0.3 0" name="table6">
        <geom size="0.3 0.01 0.1" type="box" mass="2000" rgba="1 0 0 1"></geom>
    </body>
    <body pos=".9 0.25 0" name="table7">
        <geom size="0.01 .95 0.1" type="box" mass="2000" rgba="1 0 0 1"></geom>
    </body>
    <body name="car" pos="0 0 .03">
      <freejoint/>
      <light name="top light" pos="0 0 2" mode="trackcom" diffuse=".4 .4 .4"/>
      <geom name="chasis" type="mesh" mesh="chasis"/>
      <geom name="front wheel" pos=".08 0 -.015" type="sphere" size=".015" condim="1" priority="1"/>
      <light name="front light" pos=".1 0 .02" dir="2 0 -1" diffuse="1 1 1"/>
      <body name="left wheel" pos="-.07 .06 0" zaxis="0 1 0">
        <joint name="left"/>
        <geom class="wheel"/>
        <site class="decor" size=".006 .025 .012"/>
        <site class="decor" size=".025 .006 .012"/>
      </body>
      <body name="right wheel" pos="-.07 -.06 0" zaxis="0 1 0">
        <joint name="right"/>
        <geom class="wheel"/>
        <site class="decor" size=".006 .025 .012"/>
        <site class="decor" size=".025 .006 .012"/>
      </body>
    <camera name="camera1" pos="2 2 2" euler="1.57 0 0" fovy="45" />

      <!-- Rangefinder sensor by Darren -->
    <site name="sensor_forward_site" pos="0.1 0 0" size="0.01" rgba="1 0 0 1" type="sphere" quat=".707 0 .707 0"></site>
    <site name="sensor_left_site" pos="0 0.03 0" size="0.01" rgba="0 1 0 1" type="sphere" quat="-.707 .707 0 0"></site>
    <site name="sensor_right_site" pos="0 -0.03 0" size="0.01" rgba="1 1 0 1" type="sphere" quat=".707 0.707 0 0"></site>
    <site name="sensor_backward_site" pos="-0.1 0 0" size="0.01" rgba="0 0 1 1" type="sphere" quat="-.707 0 .707 0"></site>
      
    </body>
  </worldbody>

  <tendon>
    <fixed name="forward">
      <joint joint="left" coef=".5"/>
      <joint joint="right" coef=".5"/>
    </fixed>
    <fixed name="turn">
      <joint joint="left" coef="-.5"/>
      <joint joint="right" coef=".5"/>
    </fixed>
  </tendon>

  <actuator>
    <motor name="forward" tendon="forward" ctrlrange="-1 1" ctrllimited="true" gear="100"/>
    <motor name="turn" tendon="turn" ctrlrange="-1 1" ctrllimited="true" gear="100"/>
  </actuator>

  <sensor>
    <actuatorfrc name="forward_force" actuator="forward"/>
    <actuatorfrc name="turn_force" actuator="turn"/>
    <rangefinder site="sensor_forward_site" name="sensor_forward" />
    <rangefinder site="sensor_right_site" name="sensor_right" />
    <rangefinder site="sensor_left_site" name="sensor_left" />
    <rangefinder site="sensor_backward_site" name="sensor_backward" />
  </sensor>

</mujoco>



